
[参考文章](https://juejin.cn/post/7011299888465969166)
```js
/**
 * 处理 async/await 异常
 *
 * 返回的方法在调用时候，resolve时将执行传入的方法fn，在失败的时候返回原因
 *
 * @param {Function} fn 返回值为thenable对象的方法
 * @return {Function} 生成数组，第一个元素为失败的原因，第二个元素是结果
 */
export const catchAwait = fn => async (...args) => {
    try {
        return [null, await fn(...args)];
    }
    catch (e) {
        return [e];
    }
};
```