<!DOCTYPE html>
<html lang="en">
<head>
    <meta charset="UTF-8">
    <meta http-equiv="X-UA-Compatible" content="IE=edge">
    <meta name="viewport" content="width=device-width, initial-scale=1.0">
    <title>异步事件循环</title>
</head>
<body>
    
</body>
<script>
    /*
        第一题
        第一次作答错误：10月20日 更正 10月25日
    */
    const promise = new Promise((resolve, reject) => {
        console.log(1);
        console.log(2);
    });
    promise.then(() => {
        console.log(3);
    });
    console.log(4);

    /*
        1
        2
        4

        解析：
        promise.then是个微任务，他的执行需要（1）同步任务都执行完成后，（2）promise内部的状态要发生变化。
        promise中并没有发生状态的流转，所以promise.then不会执行。
    */


</script>

<script>
    // 第二题
    const promise1 = new Promise((resolve, reject) => {
        console.log('promise1')
        resolve('resolve1')
    })

    const promise2 = promise1.then(res => {
        console.log(res)
    })
    console.log('1', promise1);
    console.log('2', promise2);

    /*
        promise1
        1 <Promise> // 修改 Promise{<fulfilled>: resolve1}
        2 <Promise> // Promise{<pending>}
        resolve1
    */

    /*
    解析：
    1. Promise 新建后就会立即执行。  ---> promise1  
    2. 遇到resolve promise1 状态变为  fulfilled 并存在结果
    3. promise1.then  // 微任务，加入任务队列
    4. promise2 是一个promise pending状态
    */

</script>

<script>
    // 第三题
    const promise = new Promise((resolve, reject) => {
        console.log(1);
        setTimeout(() => {
            console.log("timerStart");
            resolve("success");
            console.log("timerEnd");
        }, 0);
        console.log(2);
    });

    promise.then((res) => {
        console.log(res);
    });

    console.log(4);

    /*
        1
        2
        4
        tiemrStart
        timeEnd
        success
    */

</script>

<script>
    /*
        第四题
        第一次作答错误：10月20
    */
    Promise.resolve().then(() => {
        console.log('promise1');
        const timer2 = setTimeout(() => {
            console.log('timer2')
        }, 0)
    });

    const timer1 = setTimeout(() => {
        console.log('timer1')
        Promise.resolve().then(() => {
            console.log('promise2')
        })
    }, 0)

    console.log('start');

    /*
        start
        promise1
        timer1
        promise2
        timer2

        解释：
        1. 首先，Promise.resolve().then是一个微任务，加入微任务队列
        2. 执行timer1，它是一个宏任务，加入宏任务队列
        3. 继续执行下面的同步代码，打印出start
        4. 这样第一轮同步任务就执行完了，开始执行微任务Promise.resolve().then，打印出promise1
        5. 遇到timer2，它是一个宏任务，将其加入宏任务队列，此时宏任务队列有两个任务，分别是timer1、timer2；
        6. 这样第一轮微任务就执行完了，开始执行第二轮宏任务，首先执行定时器timer1，打印timer1；
        7. 遇到Promise.resolve().then，它是一个微任务，加入微任务队列
        8. 开始执行微任务队列中的任务，打印promise2；
        9. 最后执行宏任务timer2定时器，打印出timer2；

    */
</script>

<script>
    // 第五题
    const promise = new Promise((resolve, reject) => {
        resolve('success1');
        reject('error');
        resolve('success2');
    });

    promise.then((res) => {
        console.log('then:', res);
    }).catch((err) => {
        console.log('catch:', err);
    })

    /*
        then:success1
    */

</script>

<script>
    // 第六题
    // 没有作对 10月25日
    Promise.resolve(1)
    .then(2)
    .then(Promise.resolve(3))
    .then(res => {
        console.log('res---', res)
    })

    /*
    1

    1. Promise.resolve方法的参数如果是一个原始值, 或者是一个不具有then方法的对象，则Promise.resolve方法返回一个新的Promise对象，状态为resolved。
    Promise.resolve方法的参数，会同时传给回调函数。

    2. then方法接受的参数是函数，而如果传递的并非是一个函数，它实际上会将其解释为then(null)，这就会导致前一个Promise的结果会传递下面。
    
    3. .then 或.catch 的参数期望是函数，传入非函数则会发生值透传。
    第一个then和第二个then中传入的都不是函数，一个是数字，一个是对象，
    因此发生了透传，将resolve(1) 的值直接传到最后一个then里，直接打印出1。
    */
</script>
<script>
    // 第七题
    const promise1 = new Promise((resolve, reject) => {
        setTimeout(() => {
            resolve('success')
        }, 1000)
    })

    const promise2 = promise1.then(() => {
        throw new Error('error!!!')
    })

    console.log('promise1', promise1)
    console.log('promise2', promise2)

    setTimeout(() => {
        console.log('promise1', promise1)
        console.log('promise2', promise2)
    }, 2000)

    /*
        promise1  Promise<{pending}>
        promise2  Promise<{pending}>
        // 这个异常没有写出来
        Uncaught (in promise) Error: error!!!

        promise1  Promise<{fullfilled} success>
        promise2  Promise<{rejected} error!!!>
    */
</script>
<script>
    // 第八题
    Promise.resolve(1)
    .then(res => {
        console.log('1---', res);
        return 2;
    })
    .catch(err => {
        return 3;
    })
    .then(res => {
        console.log('2---', res);
    });

  

    /*
    1
    2
    */
</script>
<script>
    // 9  做错了
    Promise.resolve().then(() => {
        return new Error('error!!!')
    }).then(res => {
        console.log("then: ", res)
    }).catch(err => {
        console.log("catch: ", err)
    })

    /*
        catch: error!!! // 错误
        then: error!!!

        返回任意一个非 promise 的值都会被包裹成 promise 对象，
        因此这里的return new Error('error!!!')也被包裹成了return Promise.resolve(new Error('error!!!'))，
        因此它会被then捕获而不是catch。
    */

</script>
<script> 
    // 10  做错了
    const promise = Promise.resolve().then(() => {
        return promise;
    })
    promise.catch(console.err)

    /*
        
        死循环
        Uncaught (in promise) TypeError: Chaining cycle detected for promise #<Promise>
        .then 或 .catch 返回的值不能是 promise 本身，否则会造成死循环。
    */
</script>
<script>
    // 11和6重复

</script>
<script>
    // 12
    Promise.reject('err!!!')
    .then((res) => {
        console.log('success', res)
    }, (err) => {
        console.log('error', err)
    }).catch(err => {
        console.log('catch', err)
    })

    /*
        error err!!!

        .then函数中的两个参数：

        第一个参数是用来处理Promise成功的函数
        第二个则是处理失败的函数

        也就是说Promise.resolve('1')的值会进入成功的函数，Promise.reject('2')的值会进入失败的函数。
        在这道题中，错误直接被then的第二个参数捕获了，所以就不会被catch捕获了，输出结果为：error err!!!'
    */

    Promise.resolve()
    .then(function success (res) {
        throw new Error('error!!!')
    }, function fail1 (err) {
        console.log('fail1', err)
    }).catch(function fail2 (err) {
        console.log('fail2', err)
    })

    /*
        fail2 error!!!

        在then的第一参数中抛出了错误，那么他就不会被第二个参数不活了，而是被后面的catch捕获到。
    */
</script>

<script>
    // 13
    Promise.resolve('1')
    .then(res => {
        console.log(res)
    })
    .finally(() => {
        console.log('finally')
    })

    Promise.resolve('2')
    .finally(() => {
        console.log('finally2')
        return '我是finally2返回的值'
    })
    .then(res => {
        console.log('finally2后面的then函数', res)
    })

    /*
    错误
        1
        finally2后面的then函数 2
        finally
        finally2
    正确
        1
        finally2
        finally
        finally2后面的then函数 2
    
    补充：关于finally

    .finally()一般用的很少，只要记住以下几点就可以了：
    .finally()方法不管Promise对象最后的状态如何都会执行
    .finally()方法的回调函数不接受任何的参数，也就是说你在.finally()函数中是无法知道Promise最终的状态是resolved还是rejected的
    它最终返回的默认会是一个上一次的Promise对象值，不过如果抛出的是一个异常则返回异常的Promise对象。
    finally本质上是then方法的特例  
    */

    Promise.resolve('1')
    .finally(() => {
        console.log('finally1')
        throw new Error('我是finally中抛出的异常')
    })
    .then(res => {
        console.log('finally后面的then函数', res)
    })
    .catch(err => {
        console.log('捕获错误', err)
    })

    /*
        finally1
        捕获错误 我是finally中抛出的异常
    */

</script>
<script>
    // 14
    function runAsync (x) {
        const p = new Promise(r => 
            setTimeout(() => 
                r(x, console.log(x)),1000)
        )
        return p
    }
    Promise.all(
        [runAsync(1), runAsync(2), runAsync(3)]
    ).then(res => console.log(res))
    /*
    1
    2
    3

        [1, 2, 3]
    */

</script>
<script>
    // 15
    function runAsync (x) {
        const p = new Promise(r => setTimeout(() => r(x, console.log(x)), 1000))
        return p
    }
    function runReject (x) {
        const p = new Promise((res, rej) => setTimeout(() => rej(`Error: ${x}`, console.log(x)), 1000 * x))
        return p
    }
    Promise.all([runAsync(1), runReject(4), runAsync(3), runReject(2)])
        .then(res => console.log(res))
        .catch(err => console.log(err))
    /*
    错误：
        1
        3
        2
        4
        Error: 4
    正确：
    // 1s后输出
        1
        3
    // 2s后输出
        2
        Error: 2
    // 4s后输出
        4

    catch捕获到了第一个错误，在这道题目中最先的错误就是runReject(2)的结果。如果一组异步操作中有一个异常都不会进入.then()的

    */

</script>

<script>
    // 16
    function runAsync (x) {
        const p = new Promise(r => setTimeout(() => r(x, console.log(x)), 1000))
        return p
    }

    Promise.race([runAsync(1), runAsync(2), runAsync(3)])
    .then(res => console.log('result: ', res))
    .catch(err => console.log(err))

    /*
    错误：
        1
        2
        3
        result: [1]
    正确：
        1
        result: 1
        2
        3

    then只会捕获第一个成功的方法，其他的函数虽然还会继续执行，但是不是被then捕获了
    */

</script>
<script>
    // 17
    function runAsync(x) {
        const p = new Promise(r =>
            setTimeout(() => r(x, console.log(x)), 1000)
        );
        return p;
    }

    function runReject(x) {
        const p = new Promise((res, rej) =>
            setTimeout(() => rej(`Error: ${x}`, console.log(x)), 1000 * x)
        );
        return p;
    }

    Promise.race([runReject(0), runAsync(1), runAsync(2), runAsync(3)])
    .then(res => console.log("result: ", res))
    .catch(err => console.log(err));

    /*
       0
       Error: 0
       1
       2
       3 
    */

</script>
<script>
    // 18
    async function async1() {
        console.log("async1 start");
        await async2();
        console.log("async1 end");
    }
    async function async2() {
        console.log("async2");
    }
    async1();
    console.log('start')

    /*
        async1 start 
        async2 
        start
        async1 end
    */

</script>
<script>
    // 19
    async function async1() {
        console.log("async1 start");
        await async2();
        console.log("async1 end");
        setTimeout(() => {
            console.log('timer1')
        }, 0)
    }

    async function async2() {
        setTimeout(() => {
            console.log('timer2')
        }, 0)
        console.log("async2");
    }

    async1();

    setTimeout(() => {
        console.log('timer3')
    }, 0);

    console.log("start");

    /*
    错误：
        async1 start
        async2
        start
        timer2   x
        async1 end x
        timer3
        timer1

    正确：
        async1 start
        async2
        start
        async1 end
        timer2
        timer3
        timer1

    1. 首先进入async1，打印出async1 start；
    2. 之后遇到async2，进入async2，遇到定时器timer2，加入宏任务队列，之后打印async2；
    3. 由于async2阻塞了后面代码的执行，所以执行后面的定时器timer3，将其加入宏任务队列，之后打印start；
    4. 然后执行async2后面的代码，打印出async1 end，遇到定时器timer1，将其加入宏任务队列；
    5. 最后，宏任务队列有三个任务，先后顺序为timer2，timer3，timer1，没有微任务，所以直接所有的宏任务按照先进先出的原则执行。

    */



</script>

<script>
    // 20
    async function async1 () {
        console.log('async1 start');
        await new Promise(resolve => {
            console.log('promise1')
        })
        console.log('async1 success');
        return 'async1 end'
    }
    console.log('srcipt start')

    async1().then(res => console.log(res))

    console.log('srcipt end')

    /*
    错误
       srcipt start 
       async1 start
       promise1
       srcipt end
       async1 success x
       async1 end  x

    正确
       srcipt start 
       async1 start
       promise1
       srcipt end

    这里需要注意的是在async1中await后面的Promise是没有返回值的，也就是它的状态始终是pending状态，
    所以在await之后的内容是不会执行的，包括async1后面的 .then
    */
</script>
<script>
    // 21
    async function async1 () {
        console.log('async1 start');

        await new Promise(resolve => {
            console.log('promise1')
            resolve('promise1 resolve')
        }).then(res => console.log(res))

        console.log('async1 success');

        return 'async1 end'
    }

    console.log('srcipt start')

    async1().then(res => console.log(res))

    console.log('srcipt end')

    /*
        srcipt start
        async1 start
        promise1
        srcipt end
        promise1 resolve
        async1 success
        async1 end
    */

</script>
<script>
    // 22
    async function async1() {
        console.log("async1 start");
        await async2();
        console.log("async1 end");
    }

    async function async2() {
        console.log("async2");
    }

    console.log("script start");

    setTimeout(function() {
        console.log("setTimeout");
    }, 0);

    async1();

    new Promise(resolve => {
        console.log("promise1");
        resolve();
    }).then(function() {
        console.log("promise2");
    });

    console.log('script end')

    /*
       script start 
       async1 start
       async2
       promise1
       script end
       async1 end
       promise2
       setTimeout
    */

</script>
<script>
    // 23
    async function async1 () {
        await async2();
        console.log('async1');
        return 'async1 success'
    }

    async function async2 () {
        return new Promise((resolve, reject) => {
            console.log('async2')
            reject('error')
        })
    }

    async1().then(res => console.log(res))

    /*
       async2 
       error

       正确：
       async2 
       Promise{<rejected>: 'error'}
        Uncaught (in promise) error

        可以看到，如果async函数中抛出了错误，就会终止错误结果，不会继续向下执行。
        如果想要让错误不足之处后面的代码执行，可以使用catch来捕获
    */

</script>

<script>
    // 24
    const first = () => (new Promise((resolve, reject) => {
        console.log(3);
        let p = new Promise((resolve, reject) => {
            console.log(7);
            setTimeout(() => {
                console.log(5);
                resolve(6);
                console.log(p)
            }, 0)
            resolve(1);
        });
        resolve(2);
        p.then((arg) => {
            console.log(arg);
        });
    }));

    first().then((arg) => {
        console.log(arg);
    });
    console.log(4);

    /*
    疑问点：p没有调用  new Promise是不是立即执行
        3
        7
        4
        1
        2
        5
        Promise{<fulfilled>: 1}


    1. 首先会进入Promise，打印出3，之后进入下面的Promise，打印出7；
    2. 遇到了定时器，将其加入宏任务队列；
    3. 执行Promise  p中的resolve，状态变为resolved，返回值为1；
    4. 执行Promise first中的resolve，状态变为resolved，返回值为2；
    5. 遇到p.then，将其加入微任务队列，遇到first().then，将其加入任务队列；
    6. 执行外面的代码，打印出4；
    7. 这样第一轮宏任务就执行完了，开始执行微任务队列中的任务，先后打印出1和2；
    8. 这样微任务就执行完了，开始执行下一轮宏任务，宏任务队列中有一个定时器，执行它，打印出5，由于执行已经变为resolved状态，所以resolve(6)不会再执行；
    9. 最后console.log(p)打印出Promise{<resolved>: 1}；
    */

</script>

<script>
    // 25
    const async1 = async () => {
        console.log('async1');
        
        setTimeout(() => {
            console.log('timer1')
        }, 2000);

        await new Promise(resolve => {
            console.log('promise1')
        });

        console.log('async1 end')
        return 'async1 success'
    } 

    console.log('script start');

    async1().then(res => console.log(res));
    console.log('script end');

    Promise.resolve(1)
        .then(2)
        .then(Promise.resolve(3))
        .catch(4)
        .then(res => console.log(res));

    setTimeout(() => {
        console.log('timer2')
    }, 1000);

    /*
    错误
        script start
        async1
        promise1
        1 X
        async1 end X
        async1 success X
        script end x
        timer1 X
        timer2 X
    正确：
        script start
        async1
        promise1
        script end
        1
        timer2
        timer1

    注意： timer的时间
    1. 首先执行同步带吗，打印出script start；
    2. 遇到定时器timer1将其加入宏任务队列；
   *3. 之后是执行Promise，打印出promise1，由于Promise没有返回值，所以后面的代码不会执行；
    4. 然后执行同步代码，打印出script end；
    5. 继续执行下面的Promise，.then和.catch期望参数是一个函数，这里传入的是一个数字，
       因此就会发生值渗透，将resolve(1)的值传到最后一个then，直接打印出1；
    6. 遇到第二个定时器，将其加入到微任务队列，执行微任务队列，按顺序依次执行两个定时器，
       但是由于定时器时间的原因，会在两秒后先打印出timer2，在四秒后打印出timer1。
    */

</script>
<script>
    // 26
    const p1 = new Promise((resolve) => {
        setTimeout(() => {
            resolve('resolve3');
            console.log('timer1')
        }, 0)
        
        resolve('resovle1');
        resolve('resolve2');
    }).then(res => {
        console.log(res)
        setTimeout(() => {
            console.log(p1)
        }, 1000)
    }).finally(res => {
        console.log('finally', res)
    })

    /*
       resovle1 
       finally: ???? // finally 不会有参数  undefined
       timer1
       Promise{<fulfilled>:resovle1}

    正确：
        resovle1 
        finally: undefined
        timer1
        Promise{<fulfilled>:undefined}

    1. 需要注意的是最后一个定时器打印出的p1其实是.finally的返回值，
    我们知道.finally的返回值如果在没有抛出错误的情况下默认会是上一个Promise的返回值，
    而这道题中.finally上一个Promise是.then()，但是这个.then()并没有返回值，
    所以p1打印出来的Promise的值会是undefined，如果在定时器的下面加上一个return 1，则值就会变成1。
    */

</script>

<script>
    // 27
    console.log('1');
    setTimeout(function() {
        console.log('2');
        process.nextTick(function() {
            console.log('3');
        })
        new Promise(function(resolve) {
            console.log('4');
            resolve();
        }).then(function() {
            console.log('5')
        })
    })
    process.nextTick(function() {
        console.log('6');
    })
    new Promise(function(resolve) {
        console.log('7');
        resolve();
    }).then(function() {
        console.log('8')
    })

    setTimeout(function() {
        console.log('9');
        process.nextTick(function() {
            console.log('10');
        })
        new Promise(function(resolve) {
            console.log('11');
            resolve();
        }).then(function() {
            console.log('12')
        })
    })

    /*
        1
        7
        6
        8
        2
        4
        3
        5
        9
        11
        10
        12
    
    （1）第一轮事件循环流程分析如下：

    1. 整体script作为第一个宏任务进入主线程，遇到console.log，输出1。
    2. 遇到setTimeout，其回调函数被分发到宏任务Event Queue中。暂且记为setTimeout1。
    3. 遇到process.nextTick()，其回调函数被分发到微任务Event Queue中。记为process1。
    4. 遇到Promise，new Promise直接执行，输出7。then被分发到微任务Event Queue中。记为then1。
    5. 又遇到了setTimeout，其回调函数被分发到宏任务Event Queue中，记为setTimeout2。

        宏任务Event Queue	微任务Event Queue
        setTimeout1	       process1
        setTimeout2	       then1

    6. 宏任务Event Queue微任务Event QueuesetTimeout1process1setTimeout2then1
    7. 上表是第一轮事件循环宏任务结束时各Event Queue的情况，此时已经输出了1和7。发现了process1和then1两个微任务：

        执行process1，输出6。
        执行then1，输出8。

    8. 第一轮事件循环正式结束，这一轮的结果是输出1，7，6，8。

    （2）第二轮时间循环从**setTimeout1**宏任务开始：

    1. 首先输出2。接下来遇到了process.nextTick()，同样将其分发到微任务Event Queue中，记为process2。
    2. new Promise立即执行输出4，then也分发到微任务Event Queue中，记为then2。

        宏任务Event Queue	微任务Event Queue
        setTimeout2	        process2
        then2

    4. 宏任务Event Queue微任务Event QueuesetTimeout2process2then2
    5. 第二轮事件循环宏任务结束，发现有process2和then2两个微任务可以执行：

        输出3。
        输出5。

    6. 第二轮事件循环结束，第二轮输出2，4，3，5。

    （3）第三轮事件循环开始，此时只剩setTimeout2了，执行。

        直接输出9。
    1. 将process.nextTick()分发到微任务Event Queue中。记为process3。
    2. 直接执行new Promise，输出11。
    3. 将then分发到微任务Event Queue中，记为then3。

        宏任务Event Queue	微任务Event Queue
                            process3
                            then3


    宏任务Event Queue微任务Event Queueprocess3then3
    第三轮事件循环宏任务执行结束，执行两个微任务process3和then3：

    输出10。
    输出12。

    第三轮事件循环结束，第三轮输出9，11，10，12。
    整段代码，共进行了三次事件循环，完整的输出为1，7，6，8，2，4，3，5，9，11，10，12。

    */

</script>

<script>
    // 28

    console.log(1)
    setTimeout(() => {
        console.log(2)
    })

    new Promise(resolve =>  {
        console.log(3)
        resolve(4)
    }).then(d => console.log(d))

    setTimeout(() => {
        console.log(5)
        new Promise(resolve =>  {
            resolve(6)
        }).then(d => console.log(d))
    })

    setTimeout(() => {
        console.log(7)
    })

    console.log(8)

    /*
        1
        3
        8
        4
        2
        5
        6
        7
    */



</script>

<script>
    // 29
    console.log(1);
    
    setTimeout(() => {
        console.log(2);
        Promise.resolve().then(() => {
            console.log(3)
        });
    });

    new Promise((resolve, reject) => {
        console.log(4)
        resolve(5)
    }).then((data) => {
        console.log(data);
    })

    setTimeout(() => {
        console.log(6);
    })

    console.log(7);

    /*
        1
        4
        7
        5
        2
        3
        6
    */

</script>

<script>
    // 30
    Promise.resolve().then(() => {
        console.log('1');
        throw 'Error';
    }).then(() => {
        console.log('2');
    }).catch(() => {
        console.log('3');
        throw 'Error';
    }).then(() => {
        console.log('4');
    }).catch(() => {
        console.log('5');
    }).then(() => {
        console.log('6');
    });

    /*
    错误
        1
        Uncatch Error 
    正确：
        1
        3
        5
        6
    */

</script>

<script>
    // 31
    setTimeout(function () {
        console.log(1);
    }, 100);

    new Promise(function (resolve) {
        console.log(2);
        resolve();
        console.log(3);
    }).then(function () {
        console.log(4);
        new Promise((resove, reject) => {
            console.log(5);
            setTimeout(() =>  {
                console.log(6);
            }, 10);
        })
    });
    console.log(7);
    console.log(8);

    /*
        2
        3
        7
        8
        4
        5
        6
        1

    */

</script>

<script>
    // 32
    console.log('script start');

setTimeout(() => {
    console.log('time1');
}, 1 * 2000);

Promise.resolve()
.then(function() {
    console.log('promise1');
}).then(function() {
    console.log('promise2');
});


async function foo() {
    await bar()
    console.log('async1 end')
}
foo()

async function errorFunc () {
    try {
        await Promise.reject('error!!!')
    } catch(e) {
        console.log(e)
    }
    console.log('async1');
    return Promise.resolve('async1 success')
}
errorFunc().then(res => console.log(res))

function bar() {
    console.log('async2 end') 
}

console.log('script end');
</script>
<script>
    // 33

    setTimeout(() => {
    console.log(1)
}, 0)

const P = new Promise((resolve, reject) => {
    console.log(2)
    setTimeout(() => {
        resolve()
        console.log(3)
    }, 0)
})

P.then(() => {
    console.log(4)
})
console.log(5)
</script>
<script>
    // 34
    var p1 = new Promise(function(resolve, reject) {
        resolve("2")
    })

    setTimeout(function(){
        console.log("1")
    },10)

    p1.then(function(value){
        console.log(value)
    })

    setTimeout(function(){
        console.log("3")
    },0)

    /*

    */
</script>

</html>